data/test_data/match.csv
_id,maker_order_id,price,product_id,sequence,side,size,taker_order_id,time,trade_id,type
5ad545ece3ae712cb8091bd6,88a7fa8d-d0ca-466e-8efd-7c930a01510b,8042.90000000,BTC-USD,5693130267,buy,0.15520000,b8f2f93a-aec2-4bbb-bb9c-01c43ad25cda,2018-04-17T00:55:11.045000Z,41766821,match
5ad54605e3ae712cb8091f86,6279e0f7-567a-4c93-9b0c-5169ce21e43d,8042.91000000,BTC-USD,5693131676,sell,0.01510000,c4af3abb-d2cf-4fcd-9fc7-bc7aa7c38a73,2018-04-17T00:55:36.145000Z,41766822,match
5ad54611e3ae712cb809218a,88a7fa8d-d0ca-466e-8efd-7c930a01510b,8042.90000000,BTC-USD,5693132452,buy,0.03890000,1e7e3262-475f-4910-9c31-6f71ddadbde8,2018-04-17T00:55:48.261000Z,41766823,match
5ad5461de3ae712cb80923eb,6279e0f7-567a-4c93-9b0c-5169ce21e43d,8042.91000000,BTC-USD,5693133369,sell,0.08110000,ec3795e7-5d19-4bc9-8d5c-54821e5545a5,2018-04-17T00:56:00.104000Z,41766824,match
5ad54629e3ae712cb8092545,6279e0f7-567a-4c93-9b0c-5169ce21e43d,8042.91000000,BTC-USD,5693133890,sell,0.16050544,de79c882-101d-4e4c-89d2-2c8443012d9e,2018-04-17T00:56:11.887000Z,41766825,match
5ad54629e3ae712cb8092547,9be966a1-7be2-452c-b5aa-c3e784461fde,8042.91000000,BTC-USD,5693133892,sell,0.00254870,de79c882-101d-4e4c-89d2-2c8443012d9e,2018-04-17T00:56:11.887000Z,41766826,match
5ad54629e3ae712cb8092549,8c0b0eab-ef7c-4685-8efc-bc44e3d5c396,8042.91000000,BTC-USD,5693133894,sell,0.04224586,de79c882-101d-4e4c-89d2-2c8443012d9e,2018-04-17T00:56:11.887000Z,41766827,match
5ad54634e3ae712cb8092671,88a7fa8d-d0ca-466e-8efd-7c930a01510b,8042.90000000,BTC-USD,5693134337,buy,0.19621489,df075d2e-e573-41ed-8775-eeb918d7ca0a,2018-04-17T00:56:23.141000Z,41766828,match
5ad54634e3ae712cb8092673,310ce4d9-ad0a-43cf-b354-cdd583df820c,8042.90000000,BTC-USD,5693134339,buy,0.18278511,df075d2e-e573-41ed-8775-eeb918d7ca0a,2018-04-17T00:56:23.141000Z,41766829,match
5ad5463fe3ae712cb809286d,8c0b0eab-ef7c-4685-8efc-bc44e3d5c396,8042.91000000,BTC-USD,5693135103,sell,0.03050000,d0dbe713-5292-4e25-a4b6-af688ce9bbdc,2018-04-17T00:56:34.495000Z,41766830,match
5ad5464ae3ae712cb80929f7,310ce4d9-ad0a-43cf-b354-cdd583df820c,8042.90000000,BTC-USD,5693135691,buy,0.02490000,2f93d34f-bf93-4c97-ad2e-c1d82d490075,2018-04-17T00:56:45.479000Z,41766831,match
5ad5464ce3ae712cb8092a3b,310ce4d9-ad0a-43cf-b354-cdd583df820c,8042.90000000,BTC-USD,5693135794,buy,0.00530204,2624cdbd-9ed7-49fc-9c80-991d6dbed306,2018-04-17T00:56:47.620000Z,41766832,match
5ad54656e3ae712cb8092c06,310ce4d9-ad0a-43cf-b354-cdd583df820c,8042.90000000,BTC-USD,5693136484,buy,0.01610000,c805dad8-26df-4b97-9dfb-fa5fc3c48f3a,2018-04-17T00:56:57.429000Z,41766833,match
5ad54663e3ae712cb8092d46,310ce4d9-ad0a-43cf-b354-cdd583df820c,8042.90000000,BTC-USD,5693136968,buy,0.00591285,4939b307-ba0e-4d13-8e0b-dd1ea0cb5f54,2018-04-17T00:57:09.876000Z,41766834,match
5ad54663e3ae712cb8092d48,59da6beb-7897-408b-8871-6c22cecbfebe,8042.90000000,BTC-USD,5693136970,buy,0.46717479,4939b307-ba0e-4d13-8e0b-dd1ea0cb5f54,2018-04-17T00:57:09.876000Z,41766835,match
5ad54663e3ae712cb8092d4a,1a09aac4-efd5-4149-b121-430311654b69,8042.90000000,BTC-USD,5693136972,buy,0.19671236,4939b307-ba0e-4d13-8e0b-dd1ea0cb5f54,2018-04-17T00:57:09.876000Z,41766836,match
5ad5466ee3ae712cb8092fb2,8c0b0eab-ef7c-4685-8efc-bc44e3d5c396,8042.91000000,BTC-USD,5693137893,sell,0.16250000,469d2539-e26b-4f87-812d-f86fb1de53dc,2018-04-17T00:57:21.741000Z,41766837,match
5ad5466fe3ae712cb8092fc7,1a09aac4-efd5-4149-b121-430311654b69,8042.90000000,BTC-USD,5693137926,buy,0.80328764,457a71b7-f138-436b-a968-c2d950c46928,2018-04-17T00:57:22.639000Z,41766838,match
5ad5466fe3ae712cb8092fc9,e38e0470-4c78-45b7-bf80-97168d39942b,8042.90000000,BTC-USD,5693137928,buy,0.19671236,457a71b7-f138-436b-a968-c2d950c46928,2018-04-17T00:57:22.639000Z,41766839,match
5ad5467be3ae712cb8093259,8c0b0eab-ef7c-4685-8efc-bc44e3d5c396,8042.91000000,BTC-USD,5693138906,sell,0.04060000,8898d2e9-05fa-4d6d-852e-3f3b5312ac20,2018-04-17T00:57:34.645000Z,41766840,match
5ad54686e3ae712cb8093383,8c0b0eab-ef7c-4685-8efc-bc44e3d5c396,8042.91000000,BTC-USD,5693139359,sell,0.04830000,416c1207-4fef-4e6d-8f38-1aa8aff1318b,2018-04-17T00:57:45.321000Z,41766841,match
5ad5468de3ae712cb809343b,8c0b0eab-ef7c-4685-8efc-bc44e3d5c396,8042.91000000,BTC-USD,5693139636,sell,0.04340006,f8a921cc-788d-4aee-98cd-ab776fd9ecd4,2018-04-17T00:57:52.456000Z,41766842,match
5ad54699e3ae712cb8093683,e38e0470-4c78-45b7-bf80-97168d39942b,8042.90000000,BTC-USD,5693140516,buy,0.80328764,f783f8b4-4932-4fb7-967a-4769240f3ade,2018-04-17T00:58:03.895000Z,41766843,match
5ad54699e3ae712cb8093685,e0e710ce-2c7e-47c7-8be1-ff6bccf2a125,8042.90000000,BTC-USD,5693140518,buy,0.00890913,f783f8b4-4932-4fb7-967a-4769240f3ade,2018-04-17T00:58:03.895000Z,41766844,match
5ad54699e3ae712cb8093687,baba9e55-896f-4063-8b43-d9a2dd028bb6,8042.90000000,BTC-USD,5693140520,buy,0.03895609,f783f8b4-4932-4fb7-967a-4769240f3ade,2018-04-17T00:58:03.895000Z,41766845,match
5ad5469ee3ae712cb8093757,8c0b0eab-ef7c-4685-8efc-bc44e3d5c396,8042.91000000,BTC-USD,5693140831,sell,0.13245408,8ef2876a-7205-454c-a0da-3ca0f1dbc7d8,2018-04-17T00:58:09.333000Z,41766846,match
5ad5469ee3ae712cb8093759,74587b93-1d61-42f0-b55b-d1f2213bab9e,8042.91000000,BTC-USD,5693140833,sell,0.11269888,8ef2876a-7205-454c-a0da-3ca0f1dbc7d8,2018-04-17T00:58:09.333000Z,41766847,match
5ad5469ee3ae712cb809375b,5c63c76f-cadb-456f-9eb1-edc6cd916918,8042.91000000,BTC-USD,5693140835,sell,0.07159900,8ef2876a-7205-454c-a0da-3ca0f1dbc7d8,2018-04-17T00:58:09.333000Z,41766848,match
5ad5469ee3ae712cb809375d,9fe86ffd-9dd6-481a-bdb2-477b2becde08,8042.91000000,BTC-USD,5693140837,sell,0.00180271,8ef2876a-7205-454c-a0da-3ca0f1dbc7d8,2018-04-17T00:58:09.333000Z,41766849,match
5ad5469ee3ae712cb809375f,919ce4c4-ce30-4355-96b5-a070556f44e2,8042.91000000,BTC-USD,5693140839,sell,0.00118104,8ef2876a-7205-454c-a0da-3ca0f1dbc7d8,2018-04-17T00:58:09.333000Z,41766850,match
5ad5469ee3ae712cb8093761,f0738db9-7136-4b44-b6c5-b04cc4dd75c1,8042.91000000,BTC-USD,5693140841,sell,0.00118096,8ef2876a-7205-454c-a0da-3ca0f1dbc7d8,2018-04-17T00:58:09.333000Z,41766851,match
5ad5469ee3ae712cb8093763,5ee2f55b-1ec6-4723-bc00-95fdb6902f0b,8042.91000000,BTC-USD,5693140843,sell,0.00118094,8ef2876a-7205-454c-a0da-3ca0f1dbc7d8,2018-04-17T00:58:09.333000Z,41766852,match
5ad5469ee3ae712cb8093765,02521745-d5dd-4144-8814-79705c7621ab,8042.91000000,BTC-USD,5693140845,sell,0.00205138,8ef2876a-7205-454c-a0da-3ca0f1dbc7d8,2018-04-17T00:58:09.333000Z,41766853,match
5ad5469ee3ae712cb8093767,c0261303-a9d5-4699-9c83-e31cca2672ba,8042.91000000,BTC-USD,5693140847,sell,0.00118116,8ef2876a-7205-454c-a0da-3ca0f1dbc7d8,2018-04-17T00:58:09.333000Z,41766854,match
5ad5469ee3ae712cb8093769,6d60ea35-9809-44c7-a642-979c481a4de3,8042.91000000,BTC-USD,5693140849,sell,0.00118116,8ef2876a-7205-454c-a0da-3ca0f1dbc7d8,2018-04-17T00:58:09.333000Z,41766855,match
5ad5469ee3ae712cb809376b,2b6018b9-4a07-4788-ae73-f5149d62d9d9,8042.91000000,BTC-USD,5693140851,sell,0.00118089,8ef2876a-7205-454c-a0da-3ca0f1dbc7d8,2018-04-17T00:58:09.333000Z,41766856,match
5ad5469ee3ae712cb809376d,a5692653-af95-4fe1-92eb-d258536c18c7,8042.91000000,BTC-USD,5693140853,sell,0.00118088,8ef2876a-7205-454c-a0da-3ca0f1dbc7d8,2018-04-17T00:58:09.333000Z,41766857,match
5ad5469ee3ae712cb809376f,5274102d-1ade-45e7-9d05-bbc72936a280,8042.91000000,BTC-USD,5693140855,sell,0.00192693,8ef2876a-7205-454c-a0da-3ca0f1dbc7d8,2018-04-17T00:58:09.333000Z,41766858,match
5ad5469ee3ae712cb8093771,340b01c7-9009-4ad0-8099-7af69ba86046,8042.91000000,BTC-USD,5693140857,sell,0.00118104,8ef2876a-7205-454c-a0da-3ca0f1dbc7d8,2018-04-17T00:58:09.333000Z,41766859,match
5ad5469ee3ae712cb8093773,8739b1ae-07d6-4626-8f65-b17539107078,8042.91000000,BTC-USD,5693140859,sell,0.00130536,8ef2876a-7205-454c-a0da-3ca0f1dbc7d8,2018-04-17T00:58:09.333000Z,41766860,match
5ad5469ee3ae712cb8093775,8a745963-3224-4306-ac0c-5a755b6f42c9,8042.91000000,BTC-USD,5693140861,sell,0.00118099,8ef2876a-7205-454c-a0da-3ca0f1dbc7d8,2018-04-17T00:58:09.333000Z,41766861,match
5ad5469ee3ae712cb8093777,e0bb1236-7d35-45d3-9b46-0ecb6852cb9f,8042.91000000,BTC-USD,5693140863,sell,0.00118091,8ef2876a-7205-454c-a0da-3ca0f1dbc7d8,2018-04-17T00:58:09.333000Z,41766862,match
